<?xml version="1.0"?>
<robot name="kuka_lwr" xmlns:xacro="http://www.ros.org/wiki/xacro">

	<!-- URDF model /-->
	
		<!-- First (shoulder) element of the arm. Fixed to its parent. -->
		<!--joint name="${parent}_kuka_lwr_base_joint" type="fixed">
			<xacro:insert_block name="origin"/>
			<origin xyz="0 0 0" rpy="0 0 0"/>
			<parent link="${parent}"/>
			<child link="kuka_lwr_base_link"/>
		</joint-->

		<!-- MODIFIED BASE LINK,SECOND LINK, FIFTH LINK-->

		<link name="kuka_lwr_base_link">
			<inertial>
				<!--<mass value="2.0"/> ORIGINAL VALUE-->
				<mass value="0.8"/>
				<origin xyz="0 0 0.055"  />
      <inertia ixx="0.003816666666667" ixy="0.0" ixz="0.0" iyy="0.003600000000000" iyz="0.0" izz="0.003816666666667"/>
			</inertial>
			<visual>
				<origin xyz="0 0 0" rpy="0 0 3.1415926535897931"/>
				<geometry>
					<!--<mesh filename="package://lwr_description/meshes/lwr4plus/visual/base.STL"/>-->
					<mesh filename="/mnt/c/Users/capot/Desktop/Joint_Decomposition/KUKA_SIM/visual/base.STL"/>
				</geometry>
				<material name="Kuka/Orange"/>
			</visual>
			<collision>
				<origin xyz="0 0 0.055" rpy="0 0 3.1415926535897931"/>
				<geometry>
					<cylinder radius="0.07" length="0.11"/>
				</geometry>
			</collision>
		</link>

		<!-- Second segment of the arm. Joint along z-axis -->
		<joint name="kuka_lwr_a1_joint" type="revolute">
			<origin xyz="0 0 0.11" rpy="0 0 0"/>
			<axis xyz="0 0 1"/>
			<limit lower="-2.9671" upper="2.9671" effort="176" velocity="1.9199" />
			<dynamics friction="10.0" damping="1.0"/>
			<parent link="kuka_lwr_base_link"/>
			<child link="kuka_lwr_1_link"/>
		</joint>

		

		<link name="kuka_lwr_1_link">
			<inertial>
				<mass value="3.29"/>
				<origin rpy="0 0 0" xyz="0 -0.06 0.130"/>
<inertia ixx="0.016058333333333" ixy="0.0" ixz="0.0" iyy="0.003525000000000" iyz="0.0" izz="0.013943333333333"/>
				<!--cuboid_inertia_def length="0.12" width="0.06" height="0.260" mass="2.35"/-->
			</inertial>
			<visual>
				<origin xyz="0 0 -0.008" rpy="0 0 3.1415926535897931"/>
				<geometry>
					<!--<mesh filename="package://lwr_description/meshes/lwr4plus/visual/link_1.STL"/>-->
					<mesh filename="/mnt/c/Users/capot/Desktop/Joint_Decomposition/KUKA_SIM/visual/link_1.STL"/>
				</geometry>
				<material name="Kuka/Orange"/>
			</visual>
			<collision>
				<origin xyz="0 0 0.0" rpy="0 0 0"/>
				<geometry>
					<sphere radius="0.07"/>
				</geometry>
			</collision>
			<collision>
				<origin xyz="0 0.06 0.2" rpy="0 0 0"/>
				<geometry>
					<sphere radius="0.07"/>
				</geometry>
			</collision>
			<collision>
				<origin xyz="0 0.03 0.1" rpy="-0.291 0 0"/>
				<geometry>
					<cylinder radius="0.07" length="0.208"/>
				</geometry>
			</collision>
		</link>

		<!-- Third segment of the arm. Joint along y-axis -->
		<joint name="kuka_lwr_a2_joint" type="revolute">
			<origin xyz="0 0 0.2005" rpy="0 0 0"/>
			<axis xyz="0 -1 0"/>
			<limit lower="-2.0944" upper="2.0944" effort="176" velocity="1.9199" />
			<dynamics friction="10.0" damping="1.0"/>
			<parent link="kuka_lwr_1_link"/>
			<child link="kuka_lwr_2_link"/>
		</joint>

		<link name="kuka_lwr_2_link">
			<inertial>
				<!-- <mass value="2.35"/>  ORIGINAL VALUE-->
				<mass value="1.175"/>
				<origin rpy="0 0 0" xyz="0 0.06 0.124"/>
				<!--cuboid_inertia_def length="0.12" width="0.06" height="0.260" mass="2.35"/-->
<inertia ixx="0.016058333333333" ixy="0.0" ixz="0.0" iyy="0.003525000000000" iyz="0.0" izz="0.013943333333333"/>
			</inertial>

			<visual>
				<origin xyz="0 0 0.0" rpy="0 0 3.1415926535897931"/>
				<geometry>
					<!--<mesh filename="package://lwr_description/meshes/lwr4plus/visual/link_2.STL"/>-->
					<mesh filename="/mnt/c/Users/capot/Desktop/Joint_Decomposition/KUKA_SIM/visual/link_2.STL"/>
				</geometry>
				<material name="Kuka/Orange"/>
			</visual>
			<collision>
				<origin xyz="0 0 0.2" rpy="0 0 0"/>
				<geometry>
					<sphere radius="0.07"/>
				</geometry>
			</collision>
			<collision>
				<origin xyz="0 -0.06 0.0" rpy="0 0 0"/>
				<geometry>
					<sphere radius="0.07"/>
				</geometry>
			</collision>
			<collision>
				<origin xyz="0 -0.03 0.1" rpy="-0.291 0 0"/>
				<geometry>
					<cylinder radius="0.07" length="0.208"/>
				</geometry>
			</collision>
		</link>

		<!-- Fourth element of the arm. z-axis -->
		<joint name="kuka_lwr_e1_joint" type="revolute">
			<origin xyz="0 0 0.20" rpy="0 0 0"/>
			<axis xyz="0 0 1"/>
			<limit lower="-2.9671" upper="2.9671" effort="100" velocity="2.2340" />
			<dynamics friction="10.0" damping="1.0"/>
			<parent link="kuka_lwr_2_link"/>
			<child link="kuka_lwr_3_link"/>
		</joint>

		

		<link name="kuka_lwr_3_link">
			<inertial>
				<!-- <mass value="2.35"/> -->
				<mass value="1.645"/>
				<origin rpy="0 0 0" xyz="0 0.06 0.130"/>
				<!--cuboid_inertia_def length="0.12" width="0.06" height="0.260" mass="2.35"/-->
<inertia ixx="0.016058333333333" ixy="0.0" ixz="0.0" iyy="0.003525000000000" iyz="0.0" izz="0.013943333333333"/>
			</inertial>

			<visual>
				<origin xyz="0 0 -0.008" rpy="0 0 3.1415926535897931"/>
				<geometry>
					<!--<mesh filename="package://lwr_description/meshes/lwr4plus/visual/link_3.STL"/>-->
					<mesh filename="/mnt/c/Users/capot/Desktop/Joint_Decomposition/KUKA_SIM/visual/link_3.STL"/>
				</geometry>
				<material name="Kuka/Orange"/>
			</visual>
			<collision>
				<origin xyz="0 0 0.0" rpy="0 0 0"/>
				<geometry>
					<sphere radius="0.07"/>
				</geometry>
			</collision>
			<collision>
				<origin xyz="0 -0.06 0.2" rpy="0 0 0"/>
				<geometry>
					<sphere radius="0.07"/>
				</geometry>
			</collision>
			<collision>
				<origin xyz="0 -0.03 0.1" rpy="0.291 0 0"/>
				<geometry>
					<cylinder radius="0.07" length="0.208"/>
				</geometry>
			</collision>
		</link>

		<!-- fifth element of the arm. x-axis -->
		<joint name="kuka_lwr_a3_joint" type="revolute">
			<origin xyz="0 0 0.20" rpy="0 0 0"/>
			<axis xyz="0 1 0"/>
			<limit lower="-2.0944" upper="2.0944" effort="100" velocity="2.2340" />
			<dynamics friction="10.0" damping="1.0"/>
			<parent link="kuka_lwr_3_link"/>
			<child link="kuka_lwr_4_link"/>
		</joint>

		

		<link name="kuka_lwr_4_link">
			<inertial>
				<mass value="2.82"/>
				<origin rpy="0 0 0" xyz="0 -0.06 0.124"/>
				<!--cuboid_inertia_def length="0.12" width="0.06" height="0.2600" mass="2.35"/-->
<inertia ixx="0.016058333333333" ixy="0.0" ixz="0.0" iyy="0.003525000000000" iyz="0.0" izz="0.013943333333333"/>
			</inertial>

			<visual>
				<origin xyz="0 0 0.0" rpy="0 0 3.1415926535897931"/>
				<geometry>
					<!--<mesh filename="package://lwr_description/meshes/lwr4plus/visual/link_4.STL"/>-->
					<mesh filename="/mnt/c/Users/capot/Desktop/Joint_Decomposition/KUKA_SIM/visual/link_4.STL"/>
				</geometry>
				<material name="Kuka/Orange"/>
			</visual>
			<collision>
			<origin xyz="0 0 0.2" rpy="0 0 0"/>
			<geometry>
				<sphere radius="0.07"/>
			</geometry>
			</collision>
			<collision>
				<origin xyz="0 0.06 0.0" rpy="0 0 0"/>
				<geometry>
					<sphere radius="0.07"/>
				</geometry>
			</collision>
			<collision>
				<origin xyz="0 0.03 0.1" rpy="0.291 0 0"/>
				<geometry>
					<cylinder radius="0.07" length="0.208"/>
				</geometry>
			</collision>
		</link>

		<!-- Sixth element of the arm. z-axis -->
		<joint name="kuka_lwr_a4_joint" type="revolute">
			<origin xyz="0 0 0.20" rpy="0 0 0"/>
			<axis xyz="0 0 1"/>
			<limit lower="-2.9671" upper="2.9671" effort="100" velocity="3.5605" /> 
			<dynamics friction="10.0" damping="1.0"/>
			<parent link="kuka_lwr_4_link"/>
			<child link="kuka_lwr_5_link"/>
		</joint>

		

		<link name="kuka_lwr_5_link">
			<inertial>
				<mass value="1.88"/> 
				<!-- <mass value="1.8"/> -->
				<origin rpy="0 0 0" xyz="0 0 0.124"/>
				<!--cuboid_inertia_def length="0.12" width="0.06" height="0.248" mass="2.35"/-->
<inertia ixx="0.016058333333333" ixy="0.0" ixz="0.0" iyy="0.003525000000000" iyz="0.0" izz="0.013943333333333"/>
			</inertial>

			<visual>
				<origin xyz="0 0 -0.008" rpy="0 0 3.1415926535897931"/>
				<geometry name="kuka_lwr_5_geom">
					<!--<mesh filename="package://lwr_description/meshes/lwr4plus/visual/link_5.STL"/>-->
					<mesh filename="/mnt/c/Users/capot/Desktop/Joint_Decomposition/KUKA_SIM/visual/link_5.STL"/>
					
				</geometry>
				<material name="Kuka/Orange"/>
			</visual>

			<collision>
				<origin xyz="0 0 0.0" rpy="0 0 0"/>
				<geometry>
					<sphere radius="0.07"/>
				</geometry>
			</collision>
			<collision>
				<origin xyz="0 0.04 0.19" rpy="0 0 0"/>
				<geometry>
					<sphere radius="0.07"/>
				</geometry>
			</collision>
			<collision>
				<origin xyz="0 0.02 0.095" rpy="-0.207 0 0"/>
				<geometry>
					<cylinder radius="0.07" length="0.198"/>
				</geometry>
			</collision>
		</link>

		<!-- Seventh element of the arm. z-axis -->
		<joint name="kuka_lwr_a5_joint" type="revolute">
			<origin xyz="0 0 0.19" rpy="0 0 0"/>
			<axis xyz="0 -1 0"/>
			<limit lower="-2.0944" upper="2.0944" effort="38" velocity="3.2114" />
			<dynamics friction="10.0" damping="1.0"/>
			<parent link="kuka_lwr_5_link"/>
			<child link="kuka_lwr_6_link"/>
		</joint>

		

		<link name="kuka_lwr_6_link">
			<inertial>
				<mass value="1.32"/>
				<origin rpy="0 0 0" xyz="0 0 0.0625"/>
				<!--cuboid_inertia_def length="0.125" width="0.125" height="0.125" mass="1.1"/-->
<inertia ixx="0.002864583333333" ixy="0.0" ixz="0.0" iyy="0.002864583333333" iyz="0.0" izz="0.002864583333333"/>
			</inertial>

			<visual>
				<origin xyz="0 0 0" rpy="0 0 3.1415926535897931"/>
				<geometry>
					<!--<mesh filename="package://lwr_description/meshes/lwr4plus/visual/link_6.STL"/>-->
					<mesh filename="/mnt/c/Users/capot/Desktop/Joint_Decomposition/KUKA_SIM/visual/link_6.STL"/>
				</geometry>
			<material name="Kuka/Grey"/>
			</visual>
			<collision>
			<origin xyz="0 -0.01 0" rpy="0 0 3.1415926535897931"/>
			<geometry>
				<sphere radius="0.08"/>
			</geometry>
			</collision>
		</link>

		<!-- Eighth element of the arm. z-axis -->
		<joint name="kuka_lwr_a6_joint" type="revolute">
			<origin xyz="0 0 0.078" rpy="0 0 0"/>
			<axis xyz="0 0 1"/>
			<limit lower="-2.9671" upper="2.9671" effort="38" velocity="3.2114" />
			<dynamics friction="10.0" damping="1.0"/>
			<parent link="kuka_lwr_6_link"/>
			<child link="kuka_lwr_7_link"/>
		</joint>

		

		<link name="kuka_lwr_7_link">
			<inertial>
				<mass value="0.25"/>
				<origin xyz="0 0 0"/>
				<!--cuboid_inertia_def length="0.1" width="0.1" height="0.1" mass="0.25"/-->
<inertia ixx="4.166666666666667e-04" ixy="0.0" ixz="0.0" iyy="4.166666666666667e-04" iyz="0.0" izz="4.166666666666667e-04"/>
			</inertial>
			<visual>
				<origin xyz="0 0 0" rpy="0 0 3.1415926535897931"/>
				<geometry>
					<!--<mesh filename="package://lwr_description/meshes/lwr4plus/visual/link_7.STL"/>-->
					<mesh filename="/mnt/c/Users/capot/Desktop/Joint_Decomposition/KUKA_SIM/visual/link_7.STL"/>
				</geometry>
			<material name="Kuka/DarkGrey"/>
			</visual>

			<collision>
			<origin xyz="0 0 0" rpy="0 0 3.1415926535897931"/>
			<geometry>
				<cylinder radius="0.04" length="0.05"/>
			</geometry>
			</collision>
		</link>

</robot>
